<?xml version="1.0" ?>
<!-- =================================================================================== -->
<!-- |    This document was autogenerated by xacro from hexapod_model.xacro            | -->
<!-- |    EDITING THIS FILE BY HAND IS NOT RECOMMENDED                                 | -->
<!-- =================================================================================== -->
<robot name="hexapod" xmlns:xacro="http://ros.org/wiki/xacro">
  <!-- Build the body frame -->
  <link name="base_link"/>
  <joint name="base_joint" type="fixed">
    <parent link="base_link"/>
    <child link="body"/>
    <origin rpy="0 0 0" xyz="0 0 0"/>
  </joint>
  <link name="body">
    <visual>
      <origin rpy="0 0 0" xyz="0 0 0"/>
      <geometry>
        <cylinder length="5" radius="5"/>
      </geometry>
      <material name="grey">
        <color rgba="0.5 0.5 0.5 1"/>
      </material>
    </visual>
  </link>
  <!-- Pi parameter -->
  <!-- Joint properties -->
  <!-- Leg macros -->
  <!-- Build robot model -->
  <joint name="RR_leg_center_joint" type="fixed">
    <origin rpy="0 0 0" xyz="177.8 -82.5 0"/>
    <parent link="body"/>
    <child link="RR_leg_center"/>
  </joint>
  <link name="RR_leg_center"/>
  <joint name="RR_coxa_joint" type="revolute">
    <origin rpy="0 0 -0.785398163397" xyz="0 0 0"/>
    <parent link="RR_leg_center"/>
    <child link="RR_coxa"/>
    <axis xyz="0 0 -1"/>
    <limit effort="10000" lower="-1.5" upper="1.5" velocity="100"/>
  </joint>
  <link name="RR_coxa">
    <visual>
      <origin rpy="0 0 0" xyz="0 0 0"/>
      <geometry>
        <cylinder length="3" radius="1"/>
      </geometry>
      <material name="">
        <color rgba="0.7 0.7 0 1"/>
      </material>
    </visual>
  </link>
  <joint name="RR_femur_joint" type="revolute">
    <origin rpy="-1.57079632679 0 0" xyz="58.93 0 0"/>
    <parent link="RR_coxa"/>
    <child link="RR_femur"/>
    <axis xyz="0 0 -1"/>
    <limit effort="10000" lower="-1.5" upper="1.5" velocity="100"/>
  </joint>
  <link name="RR_femur">
    <visual>
      <origin rpy="0 0 0" xyz="0 0 0"/>
      <geometry>
        <cylinder length="3" radius="1"/>
      </geometry>
      <material name="">
        <color rgba="0 0.7 0.7 1"/>
      </material>
    </visual>
  </link>
  <joint name="RR_tibia_joint" type="revolute">
    <origin rpy="-1.57079632679 0 0" xyz="107.98 0 0"/>
    <parent link="RR_femur"/>
    <child link="RR_tibia"/>
    <axis xyz="0 0 -1"/>
    <limit effort="10000" lower="-1.5" upper="1.5" velocity="100"/>
  </joint>
  <link name="RR_tibia">
    <visual>
      <origin rpy="0 0 0" xyz="0 0 0"/>
      <geometry>
        <cylinder length="3" radius="1"/>
      </geometry>
      <material name="">
        <color rgba="0 0.7 0.7 1"/>
      </material>
    </visual>
  </link>
  <joint name="RR_tarsus_joint" type="revolute">
    <origin rpy="3.14159265359 0 1.57079632679" xyz="87.74 0 0"/>
    <parent link="RR_tibia"/>
    <child link="RR_tarsus"/>
    <axis xyz="0 0 1"/>
    <limit effort="10000" lower="-1.5" upper="1.5" velocity="100"/>
  </joint>
  <link name="RR_tarsus">
    <visual>
      <origin rpy="0 0 0" xyz="0 0 0"/>
      <geometry>
        <cylinder length="3" radius="1"/>
      </geometry>
      <material name="">
        <color rgba="0.7 0 0.7 1"/>
      </material>
    </visual>
  </link>
  <joint name="RR_tarsus_foot_joint" type="fixed">
    <origin rpy="0 0 0" xyz="120.65 0 0"/>
    <parent link="RR_tarsus"/>
    <child link="RR_tarsus_foot"/>
  </joint>
  <link name="RR_tarsus_foot"/>
  <joint name="RM_leg_center_joint" type="fixed">
    <origin rpy="0 0 0" xyz="0.0 -133.35 0"/>
    <parent link="body"/>
    <child link="RM_leg_center"/>
  </joint>
  <link name="RM_leg_center"/>
  <joint name="RM_coxa_joint" type="revolute">
    <origin rpy="0 0 1.57079632679" xyz="0 0 0"/>
    <parent link="RM_leg_center"/>
    <child link="RM_coxa"/>
    <axis xyz="0 0 -1"/>
    <limit effort="10000" lower="-1.5" upper="1.5" velocity="100"/>
  </joint>
  <link name="RM_coxa">
    <visual>
      <origin rpy="0 0 0" xyz="0 0 0"/>
      <geometry>
        <cylinder length="3" radius="1"/>
      </geometry>
      <material name="">
        <color rgba="0.7 0.7 0 1"/>
      </material>
    </visual>
  </link>
  <joint name="RM_femur_joint" type="revolute">
    <origin rpy="-1.57079632679 0 0" xyz="58.93 0 0"/>
    <parent link="RM_coxa"/>
    <child link="RM_femur"/>
    <axis xyz="0 0 -1"/>
    <limit effort="10000" lower="-1.5" upper="1.5" velocity="100"/>
  </joint>
  <link name="RM_femur">
    <visual>
      <origin rpy="0 0 0" xyz="0 0 0"/>
      <geometry>
        <cylinder length="3" radius="1"/>
      </geometry>
      <material name="">
        <color rgba="0 0.7 0.7 1"/>
      </material>
    </visual>
  </link>
  <joint name="RM_tibia_joint" type="revolute">
    <origin rpy="-1.57079632679 0 0" xyz="107.98 0 0"/>
    <parent link="RM_femur"/>
    <child link="RM_tibia"/>
    <axis xyz="0 0 -1"/>
    <limit effort="10000" lower="-1.5" upper="1.5" velocity="100"/>
  </joint>
  <link name="RM_tibia">
    <visual>
      <origin rpy="0 0 0" xyz="0 0 0"/>
      <geometry>
        <cylinder length="3" radius="1"/>
      </geometry>
      <material name="">
        <color rgba="0 0.7 0.7 1"/>
      </material>
    </visual>
  </link>
  <joint name="RM_tarsus_joint" type="revolute">
    <origin rpy="3.14159265359 0 1.57079632679" xyz="87.74 0 0"/>
    <parent link="RM_tibia"/>
    <child link="RM_tarsus"/>
    <axis xyz="0 0 1"/>
    <limit effort="10000" lower="-1.5" upper="1.5" velocity="100"/>
  </joint>
  <link name="RM_tarsus">
    <visual>
      <origin rpy="0 0 0" xyz="0 0 0"/>
      <geometry>
        <cylinder length="3" radius="1"/>
      </geometry>
      <material name="">
        <color rgba="0.7 0 0.7 1"/>
      </material>
    </visual>
  </link>
  <joint name="RM_tarsus_foot_joint" type="fixed">
    <origin rpy="0 0 0" xyz="120.65 0 0"/>
    <parent link="RM_tarsus"/>
    <child link="RM_tarsus_foot"/>
  </joint>
  <link name="RM_tarsus_foot"/>
  <joint name="RF_leg_center_joint" type="fixed">
    <origin rpy="0 0 0" xyz="-177.8 -82.5 0"/>
    <parent link="body"/>
    <child link="RF_leg_center"/>
  </joint>
  <link name="RF_leg_center"/>
  <joint name="RF_coxa_joint" type="revolute">
    <origin rpy="0 0 0.785398163397" xyz="0 0 0"/>
    <parent link="RF_leg_center"/>
    <child link="RF_coxa"/>
    <axis xyz="0 0 -1"/>
    <limit effort="10000" lower="-1.5" upper="1.5" velocity="100"/>
  </joint>
  <link name="RF_coxa">
    <visual>
      <origin rpy="0 0 0" xyz="0 0 0"/>
      <geometry>
        <cylinder length="3" radius="1"/>
      </geometry>
      <material name="">
        <color rgba="0.7 0.7 0 1"/>
      </material>
    </visual>
  </link>
  <joint name="RF_femur_joint" type="revolute">
    <origin rpy="-1.57079632679 0 0" xyz="58.93 0 0"/>
    <parent link="RF_coxa"/>
    <child link="RF_femur"/>
    <axis xyz="0 0 -1"/>
    <limit effort="10000" lower="-1.5" upper="1.5" velocity="100"/>
  </joint>
  <link name="RF_femur">
    <visual>
      <origin rpy="0 0 0" xyz="0 0 0"/>
      <geometry>
        <cylinder length="3" radius="1"/>
      </geometry>
      <material name="">
        <color rgba="0 0.7 0.7 1"/>
      </material>
    </visual>
  </link>
  <joint name="RF_tibia_joint" type="revolute">
    <origin rpy="-1.57079632679 0 0" xyz="107.98 0 0"/>
    <parent link="RF_femur"/>
    <child link="RF_tibia"/>
    <axis xyz="0 0 -1"/>
    <limit effort="10000" lower="-1.5" upper="1.5" velocity="100"/>
  </joint>
  <link name="RF_tibia">
    <visual>
      <origin rpy="0 0 0" xyz="0 0 0"/>
      <geometry>
        <cylinder length="3" radius="1"/>
      </geometry>
      <material name="">
        <color rgba="0 0.7 0.7 1"/>
      </material>
    </visual>
  </link>
  <joint name="RF_tarsus_joint" type="revolute">
    <origin rpy="3.14159265359 0 1.57079632679" xyz="87.74 0 0"/>
    <parent link="RF_tibia"/>
    <child link="RF_tarsus"/>
    <axis xyz="0 0 1"/>
    <limit effort="10000" lower="-1.5" upper="1.5" velocity="100"/>
  </joint>
  <link name="RF_tarsus">
    <visual>
      <origin rpy="0 0 0" xyz="0 0 0"/>
      <geometry>
        <cylinder length="3" radius="1"/>
      </geometry>
      <material name="">
        <color rgba="0.7 0 0.7 1"/>
      </material>
    </visual>
  </link>
  <joint name="RF_tarsus_foot_joint" type="fixed">
    <origin rpy="0 0 0" xyz="120.65 0 0"/>
    <parent link="RF_tarsus"/>
    <child link="RF_tarsus_foot"/>
  </joint>
  <link name="RF_tarsus_foot"/>
  <joint name="LR_leg_center_joint" type="fixed">
    <origin rpy="0 0 0" xyz="177.8 82.5 0"/>
    <parent link="body"/>
    <child link="LR_leg_center"/>
  </joint>
  <link name="LR_leg_center"/>
  <joint name="LR_coxa_joint" type="revolute">
    <origin rpy="0 0 -0.785398163397" xyz="0 0 0"/>
    <parent link="LR_leg_center"/>
    <child link="LR_coxa"/>
    <axis xyz="0 0 -1"/>
    <limit effort="10000" lower="-1.5" upper="1.5" velocity="100"/>
  </joint>
  <link name="LR_coxa">
    <visual>
      <origin rpy="0 0 0" xyz="0 0 0"/>
      <geometry>
        <cylinder length="3" radius="1"/>
      </geometry>
      <material name="">
        <color rgba="0.7 0.7 0 1"/>
      </material>
    </visual>
  </link>
  <joint name="LR_femur_joint" type="revolute">
    <origin rpy="-1.57079632679 0 0" xyz="58.93 0 0"/>
    <parent link="LR_coxa"/>
    <child link="LR_femur"/>
    <axis xyz="0 0 -1"/>
    <limit effort="10000" lower="-1.5" upper="1.5" velocity="100"/>
  </joint>
  <link name="LR_femur">
    <visual>
      <origin rpy="0 0 0" xyz="0 0 0"/>
      <geometry>
        <cylinder length="3" radius="1"/>
      </geometry>
      <material name="">
        <color rgba="0 0.7 0.7 1"/>
      </material>
    </visual>
  </link>
  <joint name="LR_tibia_joint" type="revolute">
    <origin rpy="-1.57079632679 0 0" xyz="107.98 0 0"/>
    <parent link="LR_femur"/>
    <child link="LR_tibia"/>
    <axis xyz="0 0 -1"/>
    <limit effort="10000" lower="-1.5" upper="1.5" velocity="100"/>
  </joint>
  <link name="LR_tibia">
    <visual>
      <origin rpy="0 0 0" xyz="0 0 0"/>
      <geometry>
        <cylinder length="3" radius="1"/>
      </geometry>
      <material name="">
        <color rgba="0 0.7 0.7 1"/>
      </material>
    </visual>
  </link>
  <joint name="LR_tarsus_joint" type="revolute">
    <origin rpy="3.14159265359 0 1.57079632679" xyz="87.74 0 0"/>
    <parent link="LR_tibia"/>
    <child link="LR_tarsus"/>
    <axis xyz="0 0 1"/>
    <limit effort="10000" lower="-1.5" upper="1.5" velocity="100"/>
  </joint>
  <link name="LR_tarsus">
    <visual>
      <origin rpy="0 0 0" xyz="0 0 0"/>
      <geometry>
        <cylinder length="3" radius="1"/>
      </geometry>
      <material name="">
        <color rgba="0.7 0 0.7 1"/>
      </material>
    </visual>
  </link>
  <joint name="LR_tarsus_foot_joint" type="fixed">
    <origin rpy="0 0 0" xyz="120.65 0 0"/>
    <parent link="LR_tarsus"/>
    <child link="LR_tarsus_foot"/>
  </joint>
  <link name="LR_tarsus_foot"/>
  <joint name="LM_leg_center_joint" type="fixed">
    <origin rpy="0 0 0" xyz="0.0 133.35 0"/>
    <parent link="body"/>
    <child link="LM_leg_center"/>
  </joint>
  <link name="LM_leg_center"/>
  <joint name="LM_coxa_joint" type="revolute">
    <origin rpy="0 0 1.57079632679" xyz="0 0 0"/>
    <parent link="LM_leg_center"/>
    <child link="LM_coxa"/>
    <axis xyz="0 0 -1"/>
    <limit effort="10000" lower="-1.5" upper="1.5" velocity="100"/>
  </joint>
  <link name="LM_coxa">
    <visual>
      <origin rpy="0 0 0" xyz="0 0 0"/>
      <geometry>
        <cylinder length="3" radius="1"/>
      </geometry>
      <material name="">
        <color rgba="0.7 0.7 0 1"/>
      </material>
    </visual>
  </link>
  <joint name="LM_femur_joint" type="revolute">
    <origin rpy="-1.57079632679 0 0" xyz="58.93 0 0"/>
    <parent link="LM_coxa"/>
    <child link="LM_femur"/>
    <axis xyz="0 0 -1"/>
    <limit effort="10000" lower="-1.5" upper="1.5" velocity="100"/>
  </joint>
  <link name="LM_femur">
    <visual>
      <origin rpy="0 0 0" xyz="0 0 0"/>
      <geometry>
        <cylinder length="3" radius="1"/>
      </geometry>
      <material name="">
        <color rgba="0 0.7 0.7 1"/>
      </material>
    </visual>
  </link>
  <joint name="LM_tibia_joint" type="revolute">
    <origin rpy="-1.57079632679 0 0" xyz="107.98 0 0"/>
    <parent link="LM_femur"/>
    <child link="LM_tibia"/>
    <axis xyz="0 0 -1"/>
    <limit effort="10000" lower="-1.5" upper="1.5" velocity="100"/>
  </joint>
  <link name="LM_tibia">
    <visual>
      <origin rpy="0 0 0" xyz="0 0 0"/>
      <geometry>
        <cylinder length="3" radius="1"/>
      </geometry>
      <material name="">
        <color rgba="0 0.7 0.7 1"/>
      </material>
    </visual>
  </link>
  <joint name="LM_tarsus_joint" type="revolute">
    <origin rpy="3.14159265359 0 1.57079632679" xyz="87.74 0 0"/>
    <parent link="LM_tibia"/>
    <child link="LM_tarsus"/>
    <axis xyz="0 0 1"/>
    <limit effort="10000" lower="-1.5" upper="1.5" velocity="100"/>
  </joint>
  <link name="LM_tarsus">
    <visual>
      <origin rpy="0 0 0" xyz="0 0 0"/>
      <geometry>
        <cylinder length="3" radius="1"/>
      </geometry>
      <material name="">
        <color rgba="0.7 0 0.7 1"/>
      </material>
    </visual>
  </link>
  <joint name="LM_tarsus_foot_joint" type="fixed">
    <origin rpy="0 0 0" xyz="120.65 0 0"/>
    <parent link="LM_tarsus"/>
    <child link="LM_tarsus_foot"/>
  </joint>
  <link name="LM_tarsus_foot"/>
  <joint name="LF_leg_center_joint" type="fixed">
    <origin rpy="0 0 0" xyz="-177.8 82.5 0"/>
    <parent link="body"/>
    <child link="LF_leg_center"/>
  </joint>
  <link name="LF_leg_center"/>
  <joint name="LF_coxa_joint" type="revolute">
    <origin rpy="0 0 0.785398163397" xyz="0 0 0"/>
    <parent link="LF_leg_center"/>
    <child link="LF_coxa"/>
    <axis xyz="0 0 -1"/>
    <limit effort="10000" lower="-1.5" upper="1.5" velocity="100"/>
  </joint>
  <link name="LF_coxa">
    <visual>
      <origin rpy="0 0 0" xyz="0 0 0"/>
      <geometry>
        <cylinder length="3" radius="1"/>
      </geometry>
      <material name="">
        <color rgba="0.7 0.7 0 1"/>
      </material>
    </visual>
  </link>
  <joint name="LF_femur_joint" type="revolute">
    <origin rpy="-1.57079632679 0 0" xyz="58.93 0 0"/>
    <parent link="LF_coxa"/>
    <child link="LF_femur"/>
    <axis xyz="0 0 -1"/>
    <limit effort="10000" lower="-1.5" upper="1.5" velocity="100"/>
  </joint>
  <link name="LF_femur">
    <visual>
      <origin rpy="0 0 0" xyz="0 0 0"/>
      <geometry>
        <cylinder length="3" radius="1"/>
      </geometry>
      <material name="">
        <color rgba="0 0.7 0.7 1"/>
      </material>
    </visual>
  </link>
  <joint name="LF_tibia_joint" type="revolute">
    <origin rpy="-1.57079632679 0 0" xyz="107.98 0 0"/>
    <parent link="LF_femur"/>
    <child link="LF_tibia"/>
    <axis xyz="0 0 -1"/>
    <limit effort="10000" lower="-1.5" upper="1.5" velocity="100"/>
  </joint>
  <link name="LF_tibia">
    <visual>
      <origin rpy="0 0 0" xyz="0 0 0"/>
      <geometry>
        <cylinder length="3" radius="1"/>
      </geometry>
      <material name="">
        <color rgba="0 0.7 0.7 1"/>
      </material>
    </visual>
  </link>
  <joint name="LF_tarsus_joint" type="revolute">
    <origin rpy="3.14159265359 0 1.57079632679" xyz="87.74 0 0"/>
    <parent link="LF_tibia"/>
    <child link="LF_tarsus"/>
    <axis xyz="0 0 1"/>
    <limit effort="10000" lower="-1.5" upper="1.5" velocity="100"/>
  </joint>
  <link name="LF_tarsus">
    <visual>
      <origin rpy="0 0 0" xyz="0 0 0"/>
      <geometry>
        <cylinder length="3" radius="1"/>
      </geometry>
      <material name="">
        <color rgba="0.7 0 0.7 1"/>
      </material>
    </visual>
  </link>
  <joint name="LF_tarsus_foot_joint" type="fixed">
    <origin rpy="0 0 0" xyz="120.65 0 0"/>
    <parent link="LF_tarsus"/>
    <child link="LF_tarsus_foot"/>
  </joint>
  <link name="LF_tarsus_foot"/>
</robot>

